Workbook
Name _Toc153808675: Datos_Base!$A$28
Name _Toc153808676: Datos_Base!$B$28
Name _Toc153808677: Datos_Base!$C$28
Name _Toc153808678: Datos_Base!$D$28
Name _Toc153808679: Datos_Base!$E$28
Name _Toc153808680: Datos_Base!$F$28
Name _Toc153808681: Datos_Base!$G$28
Name _Toc153808682: Datos_Base!$H$28
Name _Toc153808683: Datos_Base!$A$29
Name _Toc153808684: Datos_Base!$B$29
Name _Toc153808685: Datos_Base!$C$29
Name _Toc153808686: Datos_Base!$D$29
Name _Toc153808687: Datos_Base!$E$29
Name _Toc153808688: Datos_Base!$F$29
Name _Toc153808689: Datos_Base!$G$29
Name _Toc153808690: Datos_Base!$H$29
Name _Toc153808691: Datos_Base!$A$30
Name _Toc153808692: Datos_Base!$B$30
Name _Toc153808693: Datos_Base!$C$30
Name _Toc153808694: Datos_Base!$D$30
Name _Toc153808695: Datos_Base!$E$30
Name _Toc153808696: Datos_Base!$F$30
Name _Toc153808697: Datos_Base!$G$30
Name _Toc153808698: Datos_Base!$H$30

Sheet CAPEX
B1: 2022
B2: AIC | C2: MFMI | D2: AVM | E2: Tecnintegral
B3: USD
A4: Importación | B4: =5835887500/4250 -> 1373150
A5: Suministro locales | B5: =13592578000/4250 -> 3198253.6
A6: Suministros planta | B6: =9455816000/4250 -> 2224897.9
A7: Total | B7: =SUM(B4:B6) -> 6796301.5 | C7: 6777481 | D7: =+B60*4.25 -> 9888945 | E7: =28316365000/4250 -> 6662674.1 | F7: =B7/B8 -> 15
A8: $/t RFF | B8: =+B7/15 -> 453086.77 | C8: =+C7/15 -> 451832.07 | D8: =+D7/20 -> 494447.25 | E8: =+E7/15 -> 444178.27
A9: Cogeneración | B9: =640000+220000+4500+212372+148900 -> 1225772 | C9: =1318863+172918 -> 1491781
A10: USD/kW | B10: =+B9/600 -> 2042.9533 | C10: =+C9/530 -> 2814.6811
B11: =0.06*B8 -> 27185.206 | C11: =0.06*C8 -> 27109.924 | D11: =0.06*D8 -> 29666.835 | E11: =0.06*E8 -> 26650.696
G13: Area | I13: Unidad
B14: Total | G14: Recepción | J14: =(+B15+B34+B49+C62)/4 -> 182701.9 | K14: =+J14/15 -> 12180.127 | L14: USD por capacidad de procesamiento de RFF
A15: Recepción | B15: 126118.35 | C15: =B15/$B$32 -> 0.028144443 | G15: Esterilización convencional | J15: =+(B16+B35+B50+C63)/4 -> 584219.15 | K15: =+J15/15 -> 38947.943 | L15: USD por capacidad de procesamiento de RFF
A16: Esterilización | B16: 467188.71 | C16: =B16/$B$32 -> 0.10425736 | G16: Esterilización continua | J16: =+G87 -> 576007.03 | K16: =+J16/15 -> 38400.469 | L16: USD por capacidad de procesamiento de RFF
A17: Desfrutación | B17: 98936.471 | C17: =B17/$B$32 -> 0.022078562 | G17: Prensado de raquis | J17: =+C65 -> 111769.18 | K17: =+J17/15 -> 7451.2784 | L17: USD por capacidad de procesamiento de RFF
A18: Prensado | B18: 14113.176 | C18: =B18/$B$32 -> 0.0031494821 | G18: Desfrutado | J18: =(+B17+B36+B51+C64)/4 -> 133276.05 | K18: =+J18/15 -> 8885.0701 | L18: USD por capacidad de procesamiento de RFF
A19: Extracción | B19: 157923.06 | C19: =B19/$B$32 -> 0.035241949 | G19: Extracción (digestión y prensado) | J19: =(+B19+B37+B52+C66)/4 -> 258389.81 | K19: =+J19/15 -> 17225.987 | L19: USD por capacidad de procesamiento de RFF
A20: Clarificación | B20: 356866.24 | C20: =B20/$B$32 -> 0.079637906 | G20: Clarificación dinamica | J20: =(+B41+C67)/2 -> 350515.59 | K20: =+J20/15 -> 23367.706 | L20: USD por capacidad de procesamiento de RFF
A21: Desfibración | B21: 101162.82 | C21: =B21/$B$32 -> 0.022575393 | G21: Clarificación estatica | J21: =+(B40+B20+B56)/3 -> 280446.41 | K21: =+J21/15 -> 18696.427 | L21: USD por capacidad de procesamiento de RFF
A22: Palmisteria | B22: 506554.35 | C22: =B22/$B$32 -> 0.11304215 | G22: Almacenamiento | J22: =+B26 -> 201415.29 | K22: =+J22/15 -> 13427.686 | L22: USD por capacidad de procesamiento de RFF
A23: Caldera | B23: 1076872.5 | C23: =B23/$B$32 -> 0.24031376 | G23: Palmisteria | J23: =+(B22+C70+B39)/3 -> 553487.31 | K23: =+J23/15 -> 36899.154 | L23: USD por capacidad de procesamiento de RFF
A24: Turbina | B24: 148900 | C24: =B24/$B$32 -> 0.033228372
A25: Supervisión | B25: 3529.4118 | C25: =B25/$B$32 -> 0.00078761994 | G25: Caldera media presión | J25: =(+B44+B23+C71)/3 -> 1141062.2 | K25: =+J25/15 -> 76070.813 | L25: USD por tonelada de vapor instalada
A26: Almacenamiento | B26: 201415.29 | C26: =B26/$B$32 -> 0.044947632 | G26: Turbina Contrapresiòn | J26: =+C10 -> 2814.6811 | K26: 20802 | L26: USD por kW instaldo
A27: Tanque Elevado | B27: 52196.706 | C27: =B27/$B$32 -> 0.011648164 | G27: Redes e infraestructura | J27: 107297 | K27: =+J27/15 -> 7153.1333 | L27: USD por capacidad de procesamiento de RFF
A28: Aislamiento | B28: 89133.647 | C28: =B28/$B$32 -> 0.019890974 | G28: Turbina Extracción condensación | K28: 3669 | L28: USD por kW instaldo
A29: Accesorios | B29: 205236 | C29: =B29/$B$32 -> 0.045800257 | G29: Sistema gases de combustión | K29: 11515 | L29: USD por tonelada de vapor instalada
A30: Montaje Mecanico | B30: 687941.88 | C30: =B30/$B$32 -> 0.15352041
A31: Montaje tuberia | B31: 187021.65 | C31: =B31/$B$32 -> 0.04173556
B32: =SUM(B15:B31) -> 4481110.2 | G32: Biodigestor y motor de combustión interna | K32: 2758 | L32: USD por kW instalado
G33: Limpieza metano | K33: 125 | L33: USD por Kw instaldo
A34: Recepción | B34: 115642 | C34: =+B34/$B$47 -> 0.020539707
A35: Esterilización | B35: 366594 | C35: =+B35/$B$47 -> 0.065112444
A36: Desfrutación | B36: 162000 | C36: =+B36/$B$47 -> 0.028773564 | G36: Pretratamiento mecanico | K36: 29655 | L36: USD por tonelada vapor
A37: Extracción | B37: 190618 | C37: =+B37/$B$47 -> 0.033856539 | G37: Pretratamiento termico
A38: Desfibración | B38: 110413 | C38: =+B38/$B$47 -> 0.01961096
A39: Palmistería | B39: 486085 | C39: =+B39/$B$47 -> 0.08633579 | K39: =86000/2.9 -> 29655.172
A40: Clarificación convencional | B40: 223401 | C40: =+B40/$B$47 -> 0.039679278
A41: Clarifación dinamica | B41: 268982 | C41: =+B41/$B$47 -> 0.047775129
...

Sheet LCA inventory

Sheet RFF evolution
A6: FRUTO PROCESADO 2022 (TONELADAS) | B6: PLANTA | C6: Palmaceite | D6: Aceites | E6: Extrarsa | F6: C.I. Tequendama | G6: Gradesa | H6: Padelma
B7: ENERO | C7: 7051 | D7: 25334.34 | E7: 14053 | F7: 11129 | G7: 6475.319 | H7: 3834
B8: FEBRERO | C8: 7403 | D8: 21591 | E8: 14614 | F8: 11764 | G8: 7139 | H8: 3506.55
B9: MARZO | C9: 18240.923 | D9: 21943.11 | E9: 17161 | F9: 12160 | G9: 9381.8164 | H9: 3692
B10: ABRIL | C10: 18565.827 | D10: 20593.97 | E10: 16147.008 | F10: 11271 | G10: 6810.795 | H10: 3522
B11: MAYO | C11: 17653.69 | D11: 20234 | E11: 15836.144 | F11: 12548 | G11: 5315.227 | H11: 4092.3
B12: JUNIO | C12: 15371.39 | D12: 15314.3 | E12: 15442.063 | F12: 10692 | G12: 4796 | H12: 3254.4
B13: JULIO | C13: 14873.19 | D13: 13155.33 | E13: 13069.403 | F13: 13155.33 | G13: 4488.442 | H13: 2631.58
B14: AGOSTO | C14: 13357.5 | D14: 11698.32 | E14: 14448.931 | F14: 9452 | G14: 5487 | H14: 2638
B15: SEPTIEMBRE | C15: =+AVERAGE(C14,C16) -> 13283.585 | D15: 23873.83 | E15: 15064.475 | F15: 9790 | G15: 5431.298 | H15: 2484.4
B16: OCTUBRE | C16: 13209.67 | D16: 15824.07 | E16: 14683 | F16: 9075 | G16: 6556.474 | H16: 2368
B17: NOVIEMBRE | C17: 18352.28 | D17: 6323.92 | E17: 13677 | F17: 9992 | G17: 6451.6 | H17: 2927.74
B18: DICIEMBRE | C18: 16130 | D18: 10321 | E18: 13393 | F18: 10881 | G18: 5201.39 | H18: 3669
B19: ACUMULADO | C19: 153157.47 | D19: 206207.19 | E19: 177589.02 | F19: 131909.33 | G19: 73534.361 | H19: 38619.97

Sheet MyE_LB
BI2: Calores especificos | BJ2: J kg k
BI3: Racimo fruto fresco | BJ3: 1482.68 | BK3: Nyakuma, B. B., Johari, A., Ahmad, A., & Abdullah, T. A. T. (2014). Comparative Analysis of the Calorific Fuel Properties of Empty Fruit Bunch Fiber and Briquette. Energy Procedia, 52, 466–473. https://doi.org/10.1016/j.egypro.2014.07.099
BI4: Frutos sueltos
BN12: Planta A
BH13: Estado | BI13: Description | BJ13: Fase/tipo | BK13: Temperatura | BL13: Presiòn | BM13: Enthalpy (kJ/kg) | BN13: Flujo Masico2 | BO13: Flujo energètico (kW) | BP13: Columna1
BH15: 1 | BI15: Racimo fruto fresco | BJ15: Sólido | BK15: 25 | BL15: atm | BM15: =+BJ3 -> 1482.68 | BN15: 30000 | BQ15: Planta A | BR15: Planta B | BS15: Planta C
BH17: 2 | BI17: RFF esterilizado | BJ17: Sólido | BK17: 95 | BL17: 0.4 | BM17: 2738.6 | BN17: =(100-+_xlfn.XLOOKUP(BN12,EE_PB!D15:I15,EE_PB!D24:I24))*BN15/100 -> 26461.425
BH18: 3 | BI18: Condensado esterilización | BJ18: Sólido/Fracción de aceite | BK18: 85 | BM18: 4.119 | BN18: =+_xlfn.XLOOKUP(BN12,EE_PB!D15:I15,EE_PB!D25:I25) -> 4170 | BO18: =+Tabla4[[#This Row],[Flujo Masico2]]*Tabla4[[#This Row],[Enthalpy (kJ/kg)]]/3600*(Tabla4[[#This Row],[Temperatura]]-BK15) -> 286.2705
BH19: 4 | BI19: Sterilization vent | BJ19: Vapor/Saturado | BK19: 110 | BL19: Saturación | BN19: =+BN15+BN20-BN18-BN17 -> 5739.5593
BH20: 5 | BI20: Steam | BJ20: Vapor/Saturado | BK20: 120 | BL20: 0.4 | BM20: 2738.6 | BN20: =+_xlfn.XLOOKUP(BN12,EE_PB!D15:I15,EE_PB!D23:I23) -> 6370.984 | BO20: =+Tabla4[[#This Row],[Flujo Masico2]]*Tabla4[[#This Row],[Enthalpy (kJ/kg)]]/3600 -> 4846.5491
BH22: 6 | BI22: Loose fruit | BJ22: Sólido | BN22: =+_xlfn.XLOOKUP(BN12,EE_PB!D15:I15,EE_PB!D32:I32)*BN15/100 -> 19171.425
BH23: 7 | BI23: Raw EFB | BJ23: solid | BN23: =+_xlfn.XLOOKUP(BN12,EE_PB!D15:I15,EE_PB!D27:I27)*BN15/100 -> 0
BH25: 8 | BI25: Pressed EFB | BJ25: solid/oil fraction | BN25: =+_xlfn.XLOOKUP(BN12,EE_PB!D15:I15,EE_PB!D31:I31)*BN15/100 -> 7290
BH26: 9 | BI26: EFB liquor | BJ26: liquid/oil fraction | BN26: =+_xlfn.XLOOKUP(BN12,EE_PB!D15:I15,EE_PB!D30:I30) -> 340.2 | BP26: Hora
BH28: 10 | BI28: Press liquor | BJ28: liquid/oil fraction | BN28: =+_xlfn.XLOOKUP(MyE_LB!BN12,EE_PB!D15:I15,EE_PB!D35:I35) -> 11865.671
BH29: 11 | BI29: Press cake | BJ29: solid | BN29: =+_xlfn.XLOOKUP(BN12,EE_PB!D15:I15,EE_PB!D39:I39) -> 6835.7201
BH30: 12 | BI30: Steam | BJ30: steam/saturated | BL30: 0.4 | BM30: 2738.6 | BN30: =+_xlfn.XLOOKUP(BN12,EE_PB!D15:I15,EE_PB!D34:I34) -> 2831.7987 | BO30: =+BM30*#REF!/3600 -> #REF!
BH31: 13 | BI31: Agua dilución | BJ31: water/saturated | BN31: =+_xlfn.XLOOKUP(BN12,EE_PB!D15:I15,EE_PB!D40:I40) -> 4511.7874
BH33: 15 | BI33: Clarification sludge | BJ33: liquid/oil fraction | BN33: =+_xlfn.XLOOKUP(BN12,EE_PB!D15:I15,EE_PB!D51:I51) -> 12190.921
BH34: 16 | BI34: Steam | BJ34: steam/saturated | BL34: 0.4 | BM34: 2738.6 | BN34: =+_xlfn.XLOOKUP(BN12,EE_PB!D15:I15,EE_PB!D50:I50) -> 700.7 | BO34: =+BM34*#REF!/3600 -> #REF!
BH35: 17 | BI35: Steam | BJ35: steam/saturated | BL35: 0.4 | BM35: 2738.6 | BO35: =+BM35*#REF!/3600 -> #REF!
BH36: 18 | BI36: Water | BJ36: water/saturated
BH37: 19 | BI37: CPO | BJ37: liquid/oil fraction
BH38: 20 | BI38: Fiber | BJ38: solid/oil fraction
BH39: 21 | BI39: Nuts | BJ39: solid
BH40: 22 | BI40: Kernel | BJ40: solid
BH41: 23 | BI41: PKS | BJ41: solid
BH42: 24 | BI42: Steam | BJ42: steam/saturated | BL42: 0.4 | BM42: 2738.6 | BO42: =+BM42*#REF!/3600 -> #REF!
BH43: 25 | BI43: Steam | BJ43: steam/saturated | BL43: 0.4 | BM43: 2738.6 | BO43: =+BM43*#REF!/3600 -> #REF!
BH44: 26 | BI44: Water | BJ44: water/saturated | BL44: atm
BH45: 27 | BI45: Water | BJ45: water/saturated | BL45: atm
BH46: 28 | BI46: Water | BJ46: water/saturated | BL46: atm
BH47: 29 | BI47: POME | BJ47: liquid/oil fraction | BL47: atm

Sheet Datos_Base
A1: Parametros | B1: Unidad | C1: Planta extractora
C2: Planta A | D2: Planta B | E2: Planta C | F2: Planta D | G2: Planta E | H2: Planta F
A3: Capacidad de procesamiento | B3: tRFF∙h-1 | C3: 30 | D3: 40 | E3: 30 | F3: 24 | G3: 24 | H3: 20 | L3: Biomasa | M3: Biogás | N3: Red nacional | O3: Diésel | S3: Planta A | T3: Planta B | U3: Planta C | V3: Planta D | W3: Planta E | X3: Planta F
A4: Fruto procesado | B4: tRFF∙año-1 | C4: 153157 | D4: 206207 | E4: 177589 | F4: 131909 | G4: 75534 | H4: 38620 | K4: Planta A | L4: 0 | M4: 0 | N4: 904.80459 | O4: 0 | P4: =SUM(L4:O4) -> 904.80459 | R4: Biomasa | S4: 383.80493 | T4: 0 | U4: 0 | V4: 0 | W4: 0 | X4: 0
A5: Horas de operación | B5: h∙año-1 | C5: 5105 | D5: 5155 | E5: 5920 | F5: 5496 | G5: 3147 | H5: 1931 | K5: Planta B | L5: 383.80493 | M5: 0 | N5: 95.902724 | O5: 5.336014 | P5: =SUM(L5:O5) -> 485.04367 | R5: Biogás | S5: 0 | T5: 0 | U5: 0 | V5: 553 | W5: 0 | X5: 0
A6: Tasa de extracción aceite | B6: % ACP∙tRFF-1 | C6: 20.71 | D6: 20.55 | E6: 19.68 | F6: 19.9 | G6: 20.77 | H6: 19.3 | K6: Planta C | L6: 0 | M6: 0 | N6: 356.54428 | O6: 56.122712 | P6: =SUM(L6:O6) -> 412.667 | R6: Red nacional | S6: 95.902724 | T6: 904.80459 | U6: 356.54428 | V6: 158 | W6: 384.12662 | X6: 455.84202
A7: Aceite crudo producido | B7: tACP∙año-1 | C7: 31719 | D7: 42376 | E7: 34950 | F7: 26250 | G7: 15688 | H7: 7454 | K7: Planta D | L7: 0 | M7: 0 | N7: 455.84202 | O7: 100.06288 | P7: =SUM(L7:O7) -> 555.9049 | R7: Diésel | S7: 5.336014 | T7: 0 | U7: 56.122712 | V7: 79 | W7: 35.271371 | X7: 100.06288
A8: PKO producido | B8: tPKO∙año-1 | C8: 7636 | D8: 10292 | E8: 7926 | F8: 5576 | G8: 2803 | H8: 2177 | K8: Planta E | L8: 0 | M8: 0 | N8: 384.12662 | O8: 35.271371 | P8: =SUM(L8:O8) -> 419.39799 | S8: =SUM(S4:S7) -> 485.04367 | T8: =SUM(T4:T7) -> 904.80459 | U8: =SUM(U4:U7) -> 412.667 | V8: =SUM(V4:V7) -> 790 | W8: =SUM(W4:W7) -> 419.39799 | X8: =SUM(X4:X7) -> 555.9049
A9: Humedad PKO | B9: % | C9: 6.38 | D9: 7.24 | E9: 6.78 | F9: 4.5 | G9: 6.74 | H9: 4.04 | K9: Planta F | L9: 0 | M9: 553 | N9: 158 | O9: 79 | P9: =SUM(L9:O9) -> 790
A10: Esterilización | L10: =SUM(L4:L9) -> 383.80493 | M10: =SUM(M4:M9) -> 553 | N10: =SUM(N4:N9) -> 2355.2202 | O10: =SUM(O4:O9) -> 275.79298 | P10: =SUM(P4:P9) -> 3567.8182
A11: Vapor de esterilización | B11: kgvapor∙h-1 | C11: 6371 | D11: 8060 | E11: 7036 | F11: 5292 | G11: 5153 | H11: 4060 | L11: =+L10/$P$10 -> 0.10757413 | M11: =+M10/$P$10 -> 0.15499669 | N11: =+N10/$P$10 -> 0.660129 | O11: =+O10/$P$10 -> 0.077300178
C12: =+C11/C3 -> 212.36667 | D12: =+D11/D3 -> 201.5 | E12: =+E11/E3 -> 234.53333 | F12: =+F11/F3 -> 220.5 | G12: =+G11/G3 -> 214.70833 | H12: =+H11/H3 -> 203
A13: Deshidratación del fruto | B13: % | C13: 11.8 | D13: 11.12 | E13: 12.06 | F13: 10.32 | G13: 12.32 | H13: 12.13
A14: Condensados de esterilización | B14: kg∙tRFF∙h-1 | C14: 4170 | D14: 5386 | E14: 4348 | F14: 3304 | G14: 3317 | H14: 2844
C15: =+C14/C3 -> 139 | D15: =+D14/D3 -> 134.65 | E15: =+E14/E3 -> 144.93333 | F15: =+F14/F3 -> 137.66667 | G15: =+G14/G3 -> 138.20833 | H15: =+H14/H3 -> 142.2
A16: Vapor evaporador | C16: =+(150*C3)+C12-((0.15-C13)*C3)-C15 -> 4922.8667 | D16: =+(150*D3)+D12-(0.045*D3)-D15 -> 6065.05 | E16: =+(150*E3)+E12-(0.045*E3)-E15 -> 4588.25 | F16: =+(150*F3)+F12-(0.045*F3)-F15 -> 3681.7533 | G16: =+(150*G3)+G12-(0.045*G3)-G15 -> 3675.42 | H16: =+(150*H3)+H12-(0.045*H3)-H15 -> 3059.9
C17: =+C16/C3 -> 164.09556 | D17: =+D16/D3 -> 151.62625 | E17: =+E16/E3 -> 152.94167 | F17: =+F16/F3 -> 153.40639 | G17: =+G16/G3 -> 153.1425 | H17: =+H16/H3 -> 152.995
A18: Eficiencia energpetica | B18: % | C18: =+Biomass!$W$41/Datos_Base!C12 -> 0 | D18: =+Biomass!$W$41/Datos_Base!D12 -> 0 | E18: =+Biomass!$W$41/Datos_Base!E12 -> 0 | F18: =+Biomass!$W$41/Datos_Base!F12 -> 0 | G18: =+Biomass!$W$41/Datos_Base!G12 -> 0 | H18: =+Biomass!$W$41/Datos_Base!H12 -> 0
A20: Desfrutado
A21: Raquis vacío | B21: kg∙tRFF∙h-1 | C21: 24.3 | D21: 22.5 | E21: 22.9 | F21: 18.6 | G21: 24.34 | H21: 21.35
A22: Humedad raquis | B22: % | C22: 64.3 | D22: 62.5 | E22: 66.7 | F22: 58.9 | G22: 59.7 | H22: 62.8
A23: Masa que pasa por digestor | B23: MPD∙tRFF∙h-1 | C23: 63.9 | D23: 66.38 | E23: 65.04 | F23: 71.08 | G23: 63.34 | H23: 66.52
A24: Humedad MPD | B24: % | C24: 28.7
A25: Digestión y prensado
A26: Vapor de digestión | B26: kgvapor∙h-1 | C26: 2832 | D26: 3524 | E26: 2537 | F26: 2606 | G26: 2113 | H26: 1806
A27: Licor de prensa | B27: kgLP∙h-1 | C27: 11866 | D27: 15972 | E27: 11799 | F27: 9589 | G27: 9513 | H27: 7885
A28: Aceite crudo en LP | B28: % | C28: 53 | D28: 54 | E28: 53 | F28: 50 | G28: 54 | H28: 53
A29: Agua en LP | B29: % | C29: 14 | D29: 16 | E29: 17 | F29: 15 | G29: 17 | H29: 16
A30: Residuos orgánicos en LP | B30: % | C30: 33 | D30: 31 | E30: 30 | F30: 35 | G30: 29 | H30: 31
A31: Fibra de mesocarpio | B31: tFibra∙año-1 | C31: 18073 | D31: 25776 | E31: 24862 | F31: 15829 | G31: 9444 | H31: 4831
A32: Humedad de mesocarpio | B32: % | C32: 35.2 | D32: 33.1 | E32: 38.4 | F32: 35.3 | G32: 36.6 | H32: 36.8
A33: Nueces | B33: tNuez∙año-1 | C33: 16825 | D33: 18788 | E33: 15918 | F33: 13095 | G33: 6247 | H33: 4880
A34: Humedad de nueces | B34: % | C34: 11.93 | D34: 10.82 | E34: 13.36 | F34: 12.29 | G34: 14.33 | H34: 16.47
A35: Clarificación
A36: Agua de dilución | B36: kgagua∙h-1 | C36: 4512 | D36: 6124 | E36: 4459 | F36: 3425 | G36: 3668 | H36: 2985
A37: Temperatura LP | B37: °C | C37: 80 | D37: 80 | E37: 80 | F37: 80 | G37: 80 | H37: 80
A38: Temperatura aceite clarificado | B38: °C | C38: 70 | D38: 72 | E38: 70 | F38: 72 | G38: 71 | H38: 70
A39: Aceite clarificado | B39: kgaceite∙h-1 | C39: 5477 | D39: 7342 | E39: 5250 | F39: 4125 | G39: 4450 | H39: 3405
A40: Vapor de clarificacion | B40: kgvapor∙h-1 | C40: 701 | D40: 1122 | E40: 535 | F40: 683 | G40: 513 | H40: 408
A41: Lodos de clarificación | B41: kgLodos∙h-1 | C41: 13733 | D41: 18278 | E41: 13546 | F41: 11495 | G41: 10843 | H41: 9271
...

Sheet Scenario 1
AE3: EFB
AR4: State | AS4: Description | AT4: Phase/type | AU4: Mass flow rate (kg/h) | AV4: Temperature (°C) | AW4: Pressure (Mpa) | AX4: Enthalpy (kJ/kg) | AY4: Energy flow (kW) | AZ4: SSR at turbine loaded (kg/kW) | BA4: Fractions of steam (kg) and electricity (kW) per tonne FFB | BB4: EFF boiler and Cogeneration | BC4: Fuel | BF4: Month | BG4: FFB feed (tonne) | BH4: Capacity (t/h) | BI4: POME generation (m3) | BJ4: Biogas production (Nm3) | BK4: Energy input (kWh) | BL4: Power generation (kW)
AR5: 1 | AS5: FFB | AT5: solid | AU5: 30000 | AW5: atm | BA5: =+AU5/30 -> 1000 | BF5: January | BG5: 7051 | BH5: =+BG5/30 -> 235.03333 | BI5: =0.9*BG5 -> 6345.9 | BJ5: =+BI5*998*0.0329 -> 208362.55 | BK5: =6.2*BJ5 -> 1291847.8 | BL5: =+BK5*0.28 -> 361717.39 | BM5: =+BL5/BH5 -> 1539.0046
E6: =+C13+G9-H11-E15 -> 11850 | F6: kg | AR6: 2 | AS6: Sterilized FFB | AT6: solid | AU6: =+AU5*0.881 -> 26430 | AW6: 0.4 | AX6: 2738.6 | AY6: =+AX6*AU6/3600 -> 20105.888 | BA6: =+AU6/30 -> 881 | BF6: February | BG6: 7403 | BH6: =+BG6/30 -> 246.76667 | BI6: =0.9*BG6 -> 6662.7 | BJ6: =+BI6*998*0.0329 -> 218764.42 | BK6: =6.2*BJ6 -> 1356339.4 | BL6: =+BK6*0.28 -> 379775.04 | BM6: =+BL6/BH6 -> 1539.0046
AR7: 3 | AS7: Sterilization condensate | AT7: solid/oil fraction | AU7: =0.039*AU5 -> 1170 | AW7: atm | BA7: =+AU7/30 -> 39 | BF7: March | BG7: 18240.923 | BH7: =+BG7/30 -> 608.03077 | BI7: =0.9*BG7 -> 16416.831 | BJ7: =+BI7*998*0.0329 -> 539033.5 | BK7: =6.2*BJ7 -> 3342007.7 | BL7: =+BK7*0.28 -> 935762.16 | BM7: =+BL7/BH7 -> 1539.0046
F8: 4 | M8: =(102+88+81)/3*C13/1000 -> 2710 | N8: kg | Q8: =35*0.85*C13/1000 -> 892.5 | R8: kg | U8: =45*C13/1000 -> 1350 | V8: kg | AL8: =+AU12*0.5 -> 2068.29 | AM8: 90 | AR8: 4 | AS8: Sterilization vent | AT8: steam/saturated | AU8: =+AU5+AU9-AU6-AU7 -> 11850 | AW8: atm | BA8: =+AU8/30 -> 395 | BF8: April | BG8: 18565.827 | BH8: =+BG8/30 -> 618.8609 | BI8: =0.9*BG8 -> 16709.244 | BJ8: =+BI8*998*0.0329 -> 548634.67 | BK8: =6.2*BJ8 -> 3401534.9 | BL8: =+BK8*0.28 -> 952429.79 | BM8: =+BL8/BH8 -> 1539.0046
G9: =0.315*C13 -> 9450 | H9: kg | N9: 12 | R9: 16 | V9: 17 | AD9: =+AD10/30000 -> 0.0612 | AH9: 8 | AL9: =+AL8*AM9/AM8 -> 2298.1 | AM9: 100 | AR9: 5 | AS9: Steam | AT9: steam/saturated | AU9: =315*C13/1000 -> 9450 | AW9: 0.4 | AX9: 2738.6 | AY9: =+AX9*AU9/3600 -> 7188.825 | BA9: =+AU9/30 -> 315 | BF9: May | BG9: 17653.69 | BH9: =+BG9/30 -> 588.45633 | BI9: =0.9*BG9 -> 15888.321 | BJ9: =+BI9*998*0.0329 -> 521680.31 | BK9: =6.2*BJ9 -> 3234417.9 | BL9: =+BK9*0.28 -> 905637.02 | BM9: =+BL9/BH9 -> 1539.0046
G10: 5 | AD10: 1836 | AE10: kWh | AL10: =+AL9*0.1 -> 229.81 | AR10: 6 | AS10: Loose fruit | AT10: solid | AU10: =+AU6-AU11 -> 20400 | BA10: =+AU10/30 -> 680 | BF10: June | BG10: 15371.39 | BH10: =+BG10/30 -> 512.37967 | BI10: =0.9*BG10 -> 13834.251 | BJ10: =+BI10*998*0.0329 -> 454236.56 | BK10: =6.2*BJ10 -> 2816266.7 | BL10: =+BK10*0.28 -> 788554.68 | BM10: =+BL10/BH10 -> 1539.0046
H11: =0.881*C13 -> 26430 | I11: kg | K11: 6 | L11: =+H11-I15 -> 20400 | M11: kg | O11: =+L11+M8+N16-M21 -> 20045.54 | P11: kg | S11: =0.23*C13 -> 6900 | T11: kg | X11: =+S11*0.95 -> 6555 | Y11: kg | AD11: 9 | AF11: =+AU36*AX36/1000 -> 78831.901 | AR11: 7 | AS11: Raw EFB | AT11: solid | AU11: =+AU5*0.201 -> 6030 | BA11: =+AU11/30 -> 201 | BF11: July | BG11: 14873.19 | BH11: =+BG11/30 -> 495.773 | BI11: =0.9*BG11 -> 13385.871 | BJ11: =+BI11*998*0.0329 -> 439514.37 | BK11: =6.2*BJ11 -> 2724989.1 | BL11: =+BK11*0.28 -> 762996.94 | BM11: =+BL11/BH11 -> 1539.0046
V12: 19 | AR12: 8 | AS12: Pressed EFB | AT12: solid/oil fraction | AU12: =+AU11*0.686 -> 4136.58 | BA12: =+AU12/30 -> 137.886 | BC12: =+AU12 -> 4136.58 | BF12: August | BG12: 13357.5 | BH12: =+BG12/30 -> 445.25 | BI12: =0.9*BG12 -> 12021.75 | BJ12: =+BI12*998*0.0329 -> 394724.54 | BK12: =6.2*BJ12 -> 2447292.2 | BL12: =+BK12*0.28 -> 685241.81 | BM12: =+BL12/BH12 -> 1539.0046
C13: 30000 | D13: kg | E13: 1 | I13: 2 | P13: 10 | T13: 14 | AR13: 9 | AS13: EFB liquor | AT13: liquid/oil fraction | AU13: =+AU11-AU12 -> 1893.42 | BA13: =+AU13/30 -> 63.114 | BF13: September | BG13: 13283.585 | BH13: =+BG13/30 -> 442.78617 | BI13: =0.9*BG13 -> 11955.226 | BJ13: =+BI13*998*0.0329 -> 392540.3 | BK13: =6.2*BJ13 -> 2433749.8 | BL13: =+BK13*0.28 -> 681449.96 | BM13: =+BL13/BH13 -> 1539.0046
L14: =+L15*30 -> 3015 | N14: 11 | O14: 13 | P14: 17 | R14: 15 | AR14: 10 | AS14: Press liquor | AT14: liquid/oil fraction | AU14: =+AU10+AU16+AU17-AU15 -> 19599 | BA14: =+AU14/30 -> 653.3 | BF14: October | BG14: 13209.67 | BH14: =+BG14/30 -> 440.32233 | BI14: =0.9*BG14 -> 11888.703 | BJ14: =+BI14*998*0.0329 -> 390356.05 | BK14: =6.2*BJ14 -> 2420207.5 | BL14: =+BK14*0.28 -> 677658.11 | BM14: =+BL14/BH14 -> 1539.0046
E15: =0.039*C13 -> 1170 | F15: 3 | I15: =0.201*C13 -> 6030 | J15: kg | L15: =3.35*C13/1000 -> 100.5 | M15: kWh | T15: 18 | AR15: 11 | AS15: Press cake | AT15: solid | AU15: =+AU24+AU25 -> 7710 | BA15: =+AU15/30 -> 257 | BF15: November | BG15: 18352.28 | BH15: =+BG15/30 -> 611.74267 | BI15: =0.9*BG15 -> 16517.052 | BJ15: =+BI15*998*0.0329 -> 542324.19 | BK15: =6.2*BJ15 -> 3362410 | BL15: =+BK15*0.28 -> 941474.79 | BM15: =+BL15/BH15 -> 1539.0046
N16: =0.14*C13 -> 4200 | O16: kg | P16: =180*C13/1000 -> 5400 | Q16: kg | S16: =45*C13/1000 -> 1350 | T16: kg | W16: =+U17*30 -> 180 | AF16: 1 | AH16: 2 | AK16: 4137 | AL16: kg | AR16: 12 | AS16: Steam | AT16: steam/saturated | AU16: =90.3*AU5/1000 -> 2709 | AW16: 0.4 | AX16: 2738.6 | AY16: =+AX16*AU16/3600 -> 2060.7965 | BA16: =+AU16/30 -> 90.3 | BF16: December | BG16: 16130 | BH16: =+BG16/30 -> 537.66667 | BI16: =0.9*BG16 -> 14517 | BJ16: =+BI16*998*0.0329 -> 476654.08 | BK16: =6.2*BJ16 -> 2955255.3 | BL16: =+BK16*0.28 -> 827471.49 | BM16: =+BL16/BH16 -> 1539.0046
U17: =0.0002*C13 -> 6 | V17: kWh | AR17: 13 | AS17: Water | AT17: water/saturated | AU17: =0.14*AU5 -> 4200 | BA17: =+AU17/30 -> 140
F18: =2.64*C13/1000 -> 79.2 | G18: kWh | J18: =0.0007*C13 -> 21 | K18: kWh | P18: =+O11+Q8+P16-S11+L24 -> 21331.46 | Q18: kg | R18: =2.2*C13/1000*0.8 -> 52.8 | S18: KWh | AK18: 8 | AR18: 14 | AS18: Wet CPO | AT18: liquid/oil fraction | AU18: =0.23*AU5 -> 6900 | BA18: =+AU18/30 -> 230
AR19: 15 | AS19: Clarification sludge | AT19: liquid/oil fraction | AU19: =AU13+AU14+AU20-AU18+AU21 -> 19264.92 | BA19: =+AU19/30 -> 642.164 | BF19: Pretratamiento
D20: =0.0002*C13 -> 6 | E20: kWh | H20: =0.0011*C13 -> 33 | I20: kWh | AM20: EFB dry | AR20: 16 | AS20: Steam | AT20: steam/saturated | AU20: =35*AU5/1000*0.85 -> 892.5 | AW20: 0.4 | AX20: 2738.6 | AY20: =+AX20*AU20/3600 -> 678.94458 | BA20: =+AU20/30 -> 29.75 | BF20: Q1 | BG20: =+((AU12*0.65*BG24*(BG27-BG26))+(AU12*(1-0.65)*BG23*(BG27-BG26)))/1000 -> 398.46434 | BI20: Qn | BJ20: =+BG20+BG21 -> 735.64236 | BK20: MJ
J21: 7 | M21: =(+L11+M8+N16)*0.266 -> 7264.46 | N21: kg | O21: =2.27*C13/1000 -> 68.1 | Q21: =2.2*C13/1000 -> 66 | R21: kWh | AA21: 7 | AC21: =+R29+U8 -> 3180 | AD21: kg | AR21: 17 | AS21: Water | AT21: water/saturated | AU21: =180*AU5/1000*0.7 -> 3780 | AW21: 0.4 | AX21: 2738.6 | AY21: =+AX21*AU21/3600 -> 2875.53 | BA21: =+AU21/30 -> 126 | BF21: Q2 | BG21: =+(AU12*0.65*(BH27-BH26))/1000 -> 337.17801
G22: =+P18+S16+S33+R35 -> 22681.46 | H22: kg | AC22: 8 | AI22: 3 | AR22: 18 | AS22: Steam | AT22: water/saturated | AU22: =45*AU5/1000 -> 1350 | BA22: =+AU22/30 -> 45
K23: 9 | AR23: 19 | AS23: CPO | AT23: liquid/oil fraction | AU23: =+AU18*0.95 -> 6555 | BA23: =+AU23/30 -> 218.5 | BF23: Cpw | BG23: 1.4
L24: =+I15-I30 -> 1893.42 | M24: kg | O24: =+M21-M29 -> 3334.46 | P24: kg | S24: =+O24-R29 -> 1504.46 | T24: kg | AR24: 20 | AS24: Fiber | AT24: solid/oil fraction | AU24: =0.131*AU5 -> 3930 | BA24: =+AU24/30 -> 131 | BC24: =+AU24*0.2 -> 786 | BF24: Cp EFB | BG24: 4.186
P25: 21 | S25: 22 | W25: =(+D20+F18+H20+J18+L15+Q21+O21+R18+U17+K38)*1.1 -> 475.86 | X25: kWh | AR25: 21 | AS25: Nuts | AT25: solid | AU25: =0.126*AU5 -> 3780 | BA25: =+AU25/30 -> 126
W26: =+W25/30 -> 15.862 | AG26: 4 | AR26: 22 | AS26: Kernel | AT26: solid | AU26: =+AU25-AU27 -> 1950 | BA26: =+AU26/30 -> 65 | BF26: Ti | BG26: 25 | BH26: 104.838
J27: 8 | N27: 20 | S27: 24 | AR27: 23 | AS27: PKS | AT27: solid | AU27: =0.061*AU5 -> 1830 | BA27: =+AU27/30 -> 61 | BC27: =+AU27*0.2 -> 366 | BF27: Tf | BG27: 55 | BH27: 230.24
AK28: 11 | AR28: 24 | AS28: Steam | AT28: steam/saturated | AU28: =50*AU5/1000 -> 1500 | AW28: 0.4 | AX28: 2738.6 | AY28: =+AX28*AU28/3600 -> 1141.0833 | BA28: =+AU28/30 -> 50
M29: =0.131*C13 -> 3930 | N29: kg | R29: =0.061*C13 -> 1830 | S29: kg | AR29: 25 | AS29: Steam | AT29: steam/saturated | AU29: =36*AU5/1000 -> 1080 | AW29: 0.4 | AX29: 2738.6 | AY29: =+AX29*AU29/3600 -> 821.58 | BA29: =+AU29/30 -> 36
I30: =+I15*0.686 -> 4136.58 | J30: kg | AJ30: 10 | AM30: 12 | AR30: 26 | AS30: Water | AT30: water/saturated | AU30: =+AU17+AU21 -> 7980 | AV30: 80 | AW30: atm | BA30: =+AU30/30 -> 266
AR31: 27 | AS31: Water | AT31: water/saturated | AU31: 1731 | AV31: 25 | AW31: atm | BA31: =+AU31/30 -> 57.7
O32: 26 | AR32: 28 | AS32: Water | AT32: water/saturated | AU32: =+AU30+AU31 -> 9711 | AV32: 80 | AW32: atm | BA32: =+AU32/30 -> 323.7
T33: kg | AR33: 29 | AS33: POME | AT33: liquid/oil fraction | AU33: =+AU19+AU22+AU28+AU29+AU7 -> 24364.92 | AV33: 95 | AW33: atm | BA33: =+AU33/30 -> 812.164
F34: 29
E35: =+E15+G22 -> 23851.46 | F35: kg | AG35: 5
AH36: 6 | AR36: 1 | AS36: Biomass fuel | AT36: solid | AU36: =+AU24+AU27 -> 5760 | AX36: =+((AU24*Biomass!E15)+(AU27*Biomass!G15))/AU36 -> 13686.094 | AY36: =+AX36*AU36/3600 -> 21897.75 | BA36: =+AU36/30 -> 192
Z37: =+G9+M8+Q8+U8+W39 -> 14402.5 | AA37: kg | AS37: EFB dried | AT37: solid | AU37: =+AU12*0.5*10/9 -> 2298.1 | AV37: 105 | AW37: 0.12 | AX37: =+Biomass!K15 -> 16525.628 | AY37: =+AU37*AX37/3600 -> 10549.318 | BA37: =+AU37/30 -> 76.603333
AR38: 2 | AS38: Water | AT38: water/saturated | AU38: =+AU40/0.95 -> 33726.783 | AV38: 105 | AW38: 0.12 | AX38: 546.48 | AY38: =+AU38*AX38/3600 -> 5119.7257 | BA38: =+AU38/30 -> 1124.2261
Z39: 6 | AR39: 3 | AS39: Flue gas | AT39: gas | AY39: =+(AY37+AY36)*0.2 -> 6489.4137 | BA39: =+AU39/30 -> 0
AI40: =+AI33 -> 0 | AR40: 4 | AS40: Steam | AT40: steam/superheated | AU40: =+(((AU37*AX37)+(AU36*AX36))*BB40)/(AX40-AX38) -> 32040.444 | AW40: 2 | AX40: 3463.03 | BA40: =+AU40/30 -> 1068.0148 | BB40: 0.8
AR41: 5 | AS41: Steam | AT41: steam/saturated | AU41: =+AU9+AU16+AU20+AU22 -> 14401.5 | AV41: 143.6 | AW41: 0.4 | AX41: 2738.6 | AY41: =+AU41*AX41/3600 -> 10955.541 | BA41: =+AU41/30 -> 480.05
AR42: 6 | AS42: Steam | AT42: steam/saturated | AU42: =+AU40-AU41 -> 17638.944 | AV42: 143.6 | AW42: 0.4 | AX42: 2386 | AY42: =+AU42*AX42/3600 -> 11690.7 | BA42: =+AU42/30 -> 587.9648
...

Sheet Scenario1_Actual
AP1: Ti | AQ1: 25 | AR1: 104.83 | AT1: CPw | AU1: 4.186
AP2: Tf | AQ2: 55 | AR2: 2369.8 | AT2: Cpefb | AU2: 1.4
AW3: Secado tusa
AP4: Month | AQ4: FFB feed (tonne) | AR4: Operating hours (h) | AS4: EFB (kg/h) | AT4: MF (kg/h) | AU4: PKS (kg/h) | AV4: POME generation (m3) | AW4: Q1 (kWh/kg) | AX4: Q2 | AY4: Qn
D5: =+B12+F8-G10-D15 -> 388 | E5: kg | AP5: January | AQ5: 153157 | AR5: =+AQ5/30 -> 5105.2333 | AS5: =+Tabla3[[#This Row],[FFB feed (tonne)]]*210/Tabla3[[#This Row],[Operating hours (h)]] -> 6300 | AT5: =+Tabla3[[#This Row],[FFB feed (tonne)]]*131/Tabla3[[#This Row],[Operating hours (h)]] -> 3930 | AU5: =+Tabla3[[#This Row],[FFB feed (tonne)]]*61/Tabla3[[#This Row],[Operating hours (h)]] -> 1830 | AV5: =0.9*AQ5/Tabla3[[#This Row],[Operating hours (h)]] -> 27 | AW5: =((+Tabla3[[#This Row],[EFB (kg/h)]]*0.65*$AU$1*($AQ$2-$AQ$1))+(Tabla3[[#This Row],[EFB (kg/h)]]*(1-0.65)*$AU$2*($AQ$2-$AQ$1))/3600) -> 514275.82 | AX5: =+Tabla3[[#This Row],[EFB (kg/h)]]*0.65*(AR2-AR1)/3600 -> 2576.4034
AW6: {=+Tabla3[Q1 (kWh/kg)]/6.3} -> 81631.083 | AX6: {=+Tabla3[Q2]/6.3} -> 408.95292
F8: =+B12*0.315 -> 315 | G8: kg | L8: =0.09*B12 -> 90 | M8: kg | P8: =0.005*B12 -> 5 | Q8: kg | T8: =0.045*B12 -> 45 | U8: kg
AG9: =AG26/0.9 -> 1230.3451 | AH9: kg
G10: =250+638 -> 888 | H10: kg | K10: =+B12*0.68 -> 680 | L10: kg | N10: =+K10+L8+M13-L21 -> 631.24 | O10: kg | R10: =0.23*B12 -> 230 | S10: kg | W10: =+R10*0.95 -> 218.5 | X10: kg | AC10: 46 | AD10: kg
AE11: =+(M29*12)+(P30*18.2)+(H30*16.5) -> 4384.95 | AF11: MJ
B12: 1000 | C12: kg | W12: =+R24-T29 -> 19.504 | X12: kg
M13: =0.09*B12 -> 90 | N13: kg | O13: =0.18*B12 -> 180 | P13: kg | Y13: =+O13+M13 -> 270
D15: =0.039*B12 -> 39 | E15: kg | H15: =+B12*0.201 -> 201 | I15: kg | K15: =0.0037*B12 -> 3.7 | L15: kWh
AG17: Ef. | AH17: 0.85
E18: =0.0042*B12 -> 4.2 | F18: kWh | I18: =0.0007*B12 -> 0.7 | J18: kWh | O18: =+N10+P8+O13-R10+K24 -> 674.94 | P18: kg | Q18: =0.00273*B12*(0.5) -> 1.365 | R18: kWh | U18: =0.0002*B12 -> 0.2 | V18: kWh
Y19: =+AG9-AG36-AB22-Y13-AC10 -> 401.34451 | Z19: kg
C20: =0.0002*1000 -> 0.2 | D20: kWh | G20: =0.0011*B12 -> 1.1 | H20: kWh | O20: 4.2 | P20: kWh | T20: 3 | U20: kWh | AD20: =(0.046*H30)+(0.03*P30)+(0.61*M29) -> 80.1658
L21: =(+K10+L8+M13)*0.266 -> 228.76 | M21: kg
G22: kg | AB22: =+T8+R34+J35+P8 -> 133.69 | AC22: kg | AI22: =+AE11*(1-AH17) -> 657.7425 | AJ22: MJ
K24: =+H15-H30 -> 88.7 | L24: kg | N24: =+L21-M29 -> 108.76 | O24: kg | R24: =+N24-P30 -> 48.76 | S24: kg | AI24: =+AH34*0.16 -> 31.362758 | AJ24: kW
V25: =(+C20+E18+G20+I18+K15+O20+T20+Q18+U18+F36)*1.1 -> 20.6415 | W25: kWh
AG26: =(+AE11-AI22)/3.366 -> 1107.3106 | AH26: kg
AB28: 0.27777778
M29: 120 | N29: kg | T29: =+R24*0.6 -> 29.256 | U29: kg
H30: 112.3 | I30: kg | P30: 60 | Q30: kg | AB30: =0.3+4.2+1.1+0.7+1.7+3.7+2.5+1.4+4+0.2 -> 19.8
AJ31: =+AH34-AI24 -> 164.65448 | AK31: kWh
R34: 50 | S34: kg | AE34: 728 | AF34: kg | AH34: =((+AG26*(3.366-2.9))+((AG36*(2.9-2.4))))/3.6 -> 196.01723 | AI34: kW
D35: =+D15+O18+AC10 -> 759.94 | E35: kg | J35: =0.3*H30 -> 33.69 | K35: kg | AM35: =+V25 -> 20.6415 | AN35: =+W25 -> kWh
F36: 0.1 | G36: kWh | AG36: =+AG26-AE34 -> 379.31061 | AH36: kg
Z38: =315+90+180+48+50 -> 683
V39: 33 | W39: kg | Z39: 683
H40: =+J35*0.5 -> 16.845
AM42: =+AJ31+AJ50-AM35 -> 197.22458 | AN42: kWh
T43: =+R53*0.1 -> 5.9124 | U43: kW
X44: =888-680 -> 208
AE45: =69.4/0.2777778 -> 249.83998
AA46: =208-20.8 -> 187.2 | AB46: =+AA46*0.6 -> 112.32
Z47: =208-21 -> 187
W48: 1000 | X48: 20 | Y48: =+Z47/1000*X48 -> 3.74
J49: 26 | K49: m3 | W49: 1000 | X49: 371 | Y49: =+Z47/1000*X49 -> 69.377
...

Sheet Scenario 2
D5: =+B12+F8-G10-D15 -> 388 | E5: kg
F8: =+B12*0.315 -> 315 | G8: kg | L8: =0.09*B12 -> 90 | M8: kg | P8: =0.005*B12 -> 5 | Q8: kg | T8: =0.045*B12 -> 45 | U8: kg
AG9: =AG26/0.9 -> 668.64726 | AH9: kg | AL9: =728-683 -> 45
G10: =250+638 -> 888 | H10: kg | K10: =+B12*0.68 -> 680 | L10: kg | N10: =+K10+L8+M13-L21 -> 631.24 | O10: kg | R10: =0.23*B12 -> 230 | S10: kg | W10: =+R10*0.95 -> 218.5 | X10: kg | AC10: 46 | AD10: kg
AE11: =+(M29*12)+(P30*18.2) -> 2532 | AF11: MJ
B12: 1000 | C12: kg | W12: =+R24-T29 -> 19.504 | X12: kg
M13: =0.09*B12 -> 90 | N13: kg | O13: =0.18*B12 -> 180 | P13: kg | Y13: =+O13+M13 -> 270
D15: =0.039*B12 -> 39 | E15: kg | H15: =+B12*0.201 -> 201 | I15: kg | K15: =0.0037*B12 -> 3.7 | L15: kWh
AG17: Ef. | AH17: 0.8
E18: =0.0042*B12 -> 4.2 | F18: kWh | I18: =0.0007*B12 -> 0.7 | J18: kWh | O18: =+N10+P8+O13-R10+K24 -> 607.24 | P18: kg | Q18: =0.00273*B12*(0.5) -> 1.365 | R18: kWh | U18: =0.0002*B12 -> 0.2 | V18: kWh
Y19: =+AG9-AG36-AB22-Y13-AC10 -> 155.86473 | Z19: kg
C20: =0.0002*1000 -> 0.2 | D20: kWh | G20: =0.0011*B12 -> 1.1 | H20: kWh | O20: 4.2 | P20: kWh | T20: 3 | U20: kWh
L21: =(+K10+L8+M13)*0.266 -> 228.76 | M21: kg | AD21: =+(0.03*P30)+(0.61*M29) -> 75
G22: kg | AB22: =+T8+R34+J35+P8 -> 154 | AC22: kg | AI22: =+AE11*(1-AH17) -> 506.4 | AJ22: MJ
K24: =+H15-H30 -> 21 | L24: kg | N24: =+L21-M29 -> 108.76 | O24: kg | R24: =+N24-P30 -> 48.76 | S24: kg | AI24: =+AH34*0.16 -> 13.414308 | AJ24: kW
V25: =(+C20+E18+G20+I18+K15+O20+T20+Q18+U18+F36)*1.1 -> 20.6415 | W25: kWh
AG26: =(+AE11-AI22)/3.366 -> 601.78253 | AH26: kg
M29: 120 | N29: kg | T29: =+R24*0.6 -> 29.256 | U29: kg
H30: 180 | I30: kg | P30: 60 | Q30: kg
AJ31: =+AH34-AI24 -> 70.425116 | AK31: kWh
R34: 50 | S34: kg | AE34: =+J35+R34+T8+P8+L8+F8 -> 559 | AF34: kg | AH34: =((+AG26*(3.366-2.9))+((AG36*(2.9-2.4))))/3.6 -> 83.839424 | AI34: kW
D35: =+D15+O18+AC10 -> 692.24 | E35: kg | J35: =0.3*H30 -> 54 | K35: kg | AM35: =+V25 -> 20.6415 | AN35: =+W25 -> kWh
F36: 0.1 | G36: kWh | AG36: =+AG26-AE34 -> 42.782531 | AH36: kg
V39: 33 | W39: kg
H40: =+J35*0.5 -> 27
AM42: =+AJ31+AJ50-AM35 -> 186.90582 | AN42: kWh
T43: =+R53*0.1 -> 15.2358 | U43: kW
AA48: =3082/30 -> 102.73333
J49: 67 | K49: m3
AJ50: =+R53-T43 -> 137.1222 | AK50: kWh
AB52: =180+54-27 -> 207
R53: =+J49*2.274 -> 152.358 | S53: kW | AE53: =53+165 -> 218
AE54: =137+70 -> 207
F55: =0.8778*D35 -> 607.64827 | G55: kg
H65: 56.666667 | I65: kg
G71: Revisar tanque UASP

Sheet Ster_Conv
B2: Ste 1 | C2: Ste 2 | D2: Ste 3
A3: t (min) | B3: P (PSI) | F3: 2.32 | G3: 50
A4: 0 | B4: 0 | C4: 0 | D4: 0 | F4: 0.25 | G4: =+G3*F4/F3 -> 5.387931
A5: 5 | B5: 20 | C5: 0 | D5: 0
A6: 7 | B6: 35 | C6: 0 | D6: 0
A7: 12 | B7: 5 | C7: 0 | D7: 0
A8: 16 | B8: 35 | C8: 0 | D8: 0
A9: 20 | B9: 5 | C9: 0 | D9: 0
A10: 25 | B10: 40 | C10: 0 | D10: 0
A11: 28 | B11: 40 | C11: 0 | D11: 0
A12: 30 | B12: 40 | C12: 0 | D12: 0
A13: 32 | B13: 40 | C13: 0 | D13: 0
A14: 35 | B14: 40 | C14: 20 | D14: 0
A15: 40 | B15: 40 | C15: 35 | D15: 0
A16: 45 | B16: 40 | C16: 5 | D16: 0
... A20: 65 | B20: 40 | C20: 40 | D20: 0
B21: 20 | C21: 40 | D21: 0
A22: 70 | B22: 0 | C22: 40 | D22: 0
A23: 80 | B23: 0 | C23: 40 | D23: 20
A24: 85 | B24: 0 | C24: 40 | D24: 35
A25: 90 | B25: 0 | C25: 40 | D25: 5
A26: 95 | B26: 0 | C26: 40 | D26: 35
A27: 100 | B27: 0 | C27: 40 | D27: 5
A28: 105 | B28: 0 | C28: 20 | D28: 40
A29: 110 | B29: 0 | C29: 0 | D29: 40
A30: 115 | B30: 0 | C30: 0 | D30: 40
A31: 120 | B31: 0 | C31: 0 | D31: 40
A32: 125 | B32: 0 | C32: 0 | D32: 40
A33: 130 | B33: 0 | C33: 0 | D33: 40
... A39: 160 | B39: 40 | C39: 0 | D39: 0
A40: 165 | B40: 40 | C40: 0
A41: 170 | B41: 40 | C41: 0
A42: 175 | B42: 40 | C42: 0
A43: 180 | B43: 40
B44: 40
B45: 40
B46: 40
B47: 40
B48: 40
B49: 30

Sheet Hoja1
A1: Zona | B1: POM | C1: Horas netas de operación al año | D1: Columna1 | E1: Capacidad de la Planta ( t RFF/h) | F1: Fruta procesada | G1: Energía electrica consumida | H1: Columna2 | I1: Energía eléctica consumida | J1: Volumen de agua consumida en caldera | K1: Cantidad de agua en caldera (kg) | L1: Vapor especifico (kg/t rFF) | M1: Consumo de vapor proceso (kG/h) | N1: Tusa entera generada | O1: Tusa prensada generada | P1: Cantidad Tusa Entera (Global) | Q1: Tusa por RFF | R1: Ratio Tusa:RFF | S1: Tusa a campo | T1: Fibra generada | U1: Ratio Fibra:RFF | V1: Fibra por RFF | W1: Fibra a Caldera | X1: Relación uso fibra en caldera | Y1: Cusco generado | Z1: Ratio Cuesco:RFF | AA1: Cuesco por RFF | AB1: Cuesco a Caldera | AC1: Relación uso cuesco | AD1: Cantidad efluente | AE1: Efluente por RFF | AF1: Tiene carpado de lagunas? | AG1: Tiene captura de metano? | AH1: DQO entrada Lagunas | AI1: DQO salida Lagunas | AJ1: Eficiencia de remoción DQO | AK1: Generación con vapor | AL1: Generación con biogás | AM1: Red Nacional | AN1: Generación con diesél | AO1: Biomass | AP1: Biogas | AQ1: Electric grid | AR1: Diesel | AS1: Total | AU1: Producción media Tusa (t/h) | AV1: EFB (TJ) | AW1: Potencial especifico (tusa) (MJ/ t RFF) | AX1: Potencial tusa (MW) | AY1: Producción media fibra (t/h) | AZ1: MF (TJ) | BA1: Energía fibra en caldera (TJ) | BB1: total Fibra (MW) | BC1: Fibra Caldera (MW) | BD1: Fibra cogeneración (MW) | BE1: Potencial especifico (fibra) (MJ/ t RFF) | BF1: Producción media cuesco (t/h) | BG1: PKS (TJ) | BH1: Potencial especifico (cuesco) (MJ/ t RFF) | BI1: Energía cuesco en caldera (TJ) | BJ1: Total PKS (MW) | BK1: PKS Cogen | BL1: PKS caldera (MW) | BM1: Potencial energético biomasa solida (TJ) | BN1: Potencial energético (MW) | BO1: POME (TJ) | BP1: POME (MW) | BQ1: Columna1 | BR1: Potencial especifico (POME) (MJ/ t RFF)22 | BS1: Boiler biomass energy (MJ/t RFF) | BT1: Biomass energy potential | BU1: Boiler biomass energy (MW)
A2: Norte | B2: 2 | C2: 5966 | D2: =Resumen[[#This Row],[Horas netas de operación al año]]/8760 -> 0.68105023 | E2: =F2/C2 -> 41.354677 | F2: 246722 | G2: 5398064.2 | H2: =Resumen[[#This Row],[Energía electrica consumida]]/Resumen[[#This Row],[Fruta procesada]] -> 21.879136 | I2: =G2/1000 -> 5398.0642 | J2: 120893.78 | K2: =J2*[1]Variables!$C$9 -> 1.1750875e+08 | L2: =Resumen[[#This Row],[Cantidad de agua en caldera (kg)]]/Resumen[[#This Row],[Fruta procesada]] -> 476.28 | M2: =Resumen[[#This Row],[Cantidad de agua en caldera (kg)]]/Resumen[[#This Row],[Horas netas de operación al año]] -> 19696.405 | N2: 598 | O2: 34875 | P2: 55401.571 | Q2: =P2/F2*1000 -> 224.55059 | R2: =P2/F2 -> 0.22455059 | S2: 35473 | T2: 30914 | U2: =T2/F2 -> 0.12529892 | V2: =T2*1000/F2 -> 125.29892 | W2: 26030 | X2: =W2/T2 -> 0.84201333 | Y2: 10168 | Z2: =Y2/F2 -> 0.041212377 | AA2: =AB2*1000/F2 -> 41.212377 | AB2: 10168 | AC2: =AB2/Y2 -> 1 | AD2: 135697 | AE2: =AD2/F2 -> 0.54999959 | AF2: no | AG2: no | AH2: 97777 | AI2: 4583 | AJ2: =1 -AI2/AH2 -> 0.95312804 | AM2: 1 | AO2: =$G2/$C2*AK2 -> 0 | AP2: =$G2/$C2*AL2 -> 0 | AQ2: =$G2/$C2*AM2 -> 904.80459 | AR2: =$G2/$C2*AN2 -> 0 | AS2: =AO2+AP2+AQ2+AR2 -> 904.80459 | AU2: =#REF!/#REF! -> #REF! | AV2: =(#REF!*1000*[1]Biomass_Propierties!$L$15)/1000000000 -> #REF! | AW2: =+LineaBASE[[#This Row],[EFB (TJ)]]*1000000/Resumen[[#This Row],[Fruta procesada]] -> #REF! | AX2: =+LineaBASE[[#This Row],[EFB (TJ)]]*1000000/(Resumen[[#This Row],[Horas netas de operación al año]]*3600) -> #REF! | AY2: =#REF!/#REF! -> #REF! | AZ2: =#REF!*1000*[1]Biomass_Propierties!$N$15/1000000000 -> #REF! | BA2: =#REF!*1000*[1]Biomass_Propierties!$N$15/1000000000 -> #REF! | BB2: =+LineaBASE[[#This Row],[MF (TJ)]]*1000000/(Resumen[[#This Row],[Horas netas de operación al año]]*3600) -> #REF! | BC2: =+LineaBASE[[#This Row],[Energía fibra en caldera (TJ)]]*1000000/(Resumen[[#This Row],[Horas netas de operación al año]]*3600) -> #REF! | BD2: =IF(Resumen[[#This Row],[Biomass]]=0,0,LineaBASE[[#This Row],[Fibra Caldera (MW)]]) -> 0 | BE2: =(+LineaBASE[[#This Row],[MF (TJ)]]*1000000)/Resumen[[#This Row],[Fruta procesada]] -> #REF! | BF2: =#REF!/#REF! -> #REF! | BG2: =#REF!*1000*[1]Biomass_Propierties!$O$15/1000000000 -> #REF! | BH2: =+LineaBASE[[#This Row],[PKS (TJ)]]*1000000/Resumen[[#This Row],[Fruta procesada]] -> #REF! | BI2: =#REF!*1000*[1]Biomass_Propierties!$O$15/1000000000 -> #REF! | BJ2: =+LineaBASE[[#This Row],[PKS (TJ)]]*1000000/(Resumen[[#This Row],[Horas netas de operación al año]]*3600) -> #REF! | BK2: =IF(LineaBASE[[#This Row],[Fibra cogeneración (MW)]]=0,0,LineaBASE[[#This Row],[PKS caldera (MW)]]) -> 0 | BL2: =+LineaBASE[[#This Row],[Energía cuesco en caldera (TJ)]]*1000000/(Resumen[[#This Row],[Horas netas de operación al año]]*3600) -> #REF! | BM2: =+LineaBASE[[#This Row],[EFB (TJ)]]+LineaBASE[[#This Row],[MF (TJ)]]+LineaBASE[[#This Row],[PKS (TJ)]] -> #REF! | BN2: =+LineaBASE[[#This Row],[Total PKS (MW)]]+LineaBASE[[#This Row],[total Fibra (MW)]]+LineaBASE[[#This Row],[Potencial tusa (MW)]] -> #REF! | BO2: =+[1]Scenario2!AI2 -> 0 | BP2: =LineaBASE[[#This Row],[POME (TJ)]]*1000000/(Resumen[[#This Row],[Horas netas de operación al año]]*3600) -> 0 | BQ2: =IF(Resumen[[#This Row],[Biogas]]=0,0,LineaBASE[[#This Row],[POME (MW)]]) -> 0 | BR2: =LineaBASE[[#This Row],[POME (TJ)]]*1000000/Resumen[[#This Row],[Fruta procesada]] -> 0 | BS2: =(LineaBASE[[#This Row],[Energía cuesco en caldera (TJ)]]+LineaBASE[[#This Row],[Energía fibra en caldera (TJ)]])*1000000/#REF! -> #REF! | BT2: =+LineaBASE[[#This Row],[Potencial especifico (POME) (MJ/ t RFF)22]]+LineaBASE[[#This Row],[Potencial especifico (cuesco) (MJ/ t RFF)]]+LineaBASE[[#This Row],[Potencial especifico (fibra) (MJ/ t RFF)]]+LineaBASE[[#This Row],[Potencial especifico (tusa) (MJ/ t RFF)]] -> #REF! | BU2: =LineaBASE[[#This Row],[Boiler biomass energy (MJ/t RFF)]]*Resumen[[#This Row],[Fruta procesada]]/(Resumen[[#This Row],[Horas netas de operación al año]]*3600) -> #REF!
A3: Norte | B3: 3 | C3: 6357 | D3: =Resumen[[#This Row],[Horas netas de operación al año]]/8760 -> 0.72568493 | E3: =F3/C3 -> 27.681139 | F3: 175969 | G3: 3083731 | H3: =Resumen[[#This Row],[Energía electrica consumida]]/Resumen[[#This Row],[Fruta procesada]] -> 17.524286 | I3: =G3/1000 -> 3083.731 | J3: 83534.5 | K3: =J3*[1]Variables!$C$9 -> 81195534 | L3: =Resumen[[#This Row],[Cantidad de agua en caldera (kg)]]/Resumen[[#This Row],[Fruta procesada]] -> 461.41953 | M3: =Resumen[[#This Row],[Cantidad de agua en caldera (kg)]]/Resumen[[#This Row],[Horas netas de operación al año]] -> 12772.618 | O3: 27262 | P3: 42840.286 | Q3: =P3/F3*1000 -> 243.4536 | R3: =P3/F3 -> 0.2434536 | S3: 23172.7 | T3: 20746.745 | U3: =T3/F3 -> 0.1179 | V3: =T3*1000/F3 -> 117.9 | W3: 10241.745 | X3: =W3/T3 -> 0.49365551 | Y3: 10558.14 | Z3: =Y3/F3 -> 0.06 | AA3: =AB3*1000/F3 -> 47.173877 | AB3: 8301.14 | AC3: =AB3/Y3 -> 0.78623129 | AD3: 105606 | AE3: =AD3/F3 -> 0.6001398 | AF3: no | AG3: no | AH3: 74496 | AI3: 2623 | AJ3: =1 -AI3/AH3 -> 0.96479006 | AK3: 0.7912 | AM3: 0.1977 | AN3: 0.011 | AO3: =$G3/$C3*AK3 -> 383.80493 | AP3: =$G3/$C3*AL3 -> 0 | AQ3: =$G3/$C3*AM3 -> 95.902724 | AR3: =$G3/$C3*AN3 -> 5.336014 | AS3: =AO3+AP3+AQ3+AR3 -> 485.04367 | AU3: =P2/C2 -> 9.2862171 | AV3: =(P2*1000*[1]Biomass_Propierties!$L$15)/1000000000 -> 356.25637 | AW3: =+LineaBASE[[#This Row],[EFB (TJ)]]*1000000/Resumen[[#This Row],[Fruta procesada]] -> 2024.5405 | AX3: =+LineaBASE[[#This Row],[EFB (TJ)]]*1000000/(Resumen[[#This Row],[Horas netas de operación al año]]*3600) -> 15.567108 | AY3: =T2/C2 -> 5.1816963 | AZ3: =T2*1000*[1]Biomass_Propierties!$N$15/1000000000 -> 371.60517 | BA3: =W2*1000*[1]Biomass_Propierties!$N$15/1000000000 -> 312.8965 | BB3: =+LineaBASE[[#This Row],[MF (TJ)]]*1000000/(Resumen[[#This Row],[Horas netas de operación al año]]*3600) -> 16.237794 | BC3: =+LineaBASE[[#This Row],[Energía fibra en caldera (TJ)]]*1000000/(Resumen[[#This Row],[Horas netas de operación al año]]*3600) -> 13.672439 | BD3: =IF(Resumen[[#This Row],[Biomass]]=0,0,LineaBASE[[#This Row],[Fibra Caldera (MW)]]) -> 13.672439 | BE3: =(+LineaBASE[[#This Row],[MF (TJ)]]*1000000)/Resumen[[#This Row],[Fruta procesada]] -> 2111.765 | BF3: =Y2/C2 -> 1.7043245 | BG3: =Y2*1000*[1]Biomass_Propierties!$O$15/1000000000 -> 185.36367 | BH3: =+LineaBASE[[#This Row],[PKS (TJ)]]*1000000/Resumen[[#This Row],[Fruta procesada]] -> 1053.3882 | BI3: =AB2*1000*[1]Biomass_Propierties!$O$15/1000000000 -> 185.36367 | BJ3: =+LineaBASE[[#This Row],[PKS (TJ)]]*1000000/(Resumen[[#This Row],[Horas netas de operación al año]]*3600) -> 8.0997183 | BK3: =IF(LineaBASE[[#This Row],[Fibra cogeneración (MW)]]=0,0,LineaBASE[[#This Row],[PKS caldera (MW)]]) -> 8.0997183 | BL3: =+LineaBASE[[#This Row],[Energía cuesco en caldera (TJ)]]*1000000/(Resumen[[#This Row],[Horas netas de operación al año]]*3600) -> 8.0997183 | BM3: =+LineaBASE[[#This Row],[EFB (TJ)]]+LineaBASE[[#This Row],[MF (TJ)]]+LineaBASE[[#This Row],[PKS (TJ)]] -> 913.22521 | BN3: =+LineaBASE[[#This Row],[Total PKS (MW)]]+LineaBASE[[#This Row],[total Fibra (MW)]]+LineaBASE[[#This Row],[Potencial tusa (MW)]] -> 39.90462 | BO3: =+[1]Scenario2!AI3 -> Potencial POME (TJ) | BP3: =LineaBASE[[#This Row],[POME (TJ)]]*1000000/(Resumen[[#This Row],[Horas netas de operación al año]]*3600) -> #VALUE! | BQ3: =IF(Resumen[[#This Row],[Biogas]]=0,0,LineaBASE[[#This Row],[POME (MW)]]) -> 0 | BR3: =LineaBASE[[#This Row],[POME (TJ)]]*1000000/Resumen[[#This Row],[Fruta procesada]] -> #VALUE! | BS3: =(LineaBASE[[#This Row],[Energía cuesco en caldera (TJ)]]+LineaBASE[[#This Row],[Energía fibra en caldera (TJ)]])*1000000/F2 -> 2019.5207 | BT3: =+LineaBASE[[#This Row],[Potencial especifico (POME) (MJ/ t RFF)22]]+LineaBASE[[#This Row],[Potencial especifico (cuesco) (MJ/ t RFF)]]+LineaBASE[[#This Row],[Potencial especifico (fibra) (MJ/ t RFF)]]+LineaBASE[[#This Row],[Potencial especifico (tusa) (MJ/ t RFF)]] -> #VALUE! | BU3: =LineaBASE[[#This Row],[Boiler biomass energy (MJ/t RFF)]]*Resumen[[#This Row],[Fruta procesada]]/(Resumen[[#This Row],[Horas netas de operación al año]]*3600) -> 15.528509
A4: Norte | B4: 4 | C4: 6642 | D4: =Resumen[[#This Row],[Horas netas de operación al año]]/8760 -> 0.75821918 | E4: =F4/C4 -> 24.339901 | F4: 161665.62 | G4: 2740934.2 | H4: =Resumen[[#This Row],[Energía electrica consumida]]/Resumen[[#This Row],[Fruta procesada]] -> 16.954342 | I4: =G4/1000 -> 2740.9342 | J4: 137065.6 | K4: =J4*[1]Variables!$C$9 -> 1.3322776e+08 | L4: =Resumen[[#This Row],[Cantidad de agua en caldera (kg)]]/Resumen[[#This Row],[Fruta procesada]] -> 824.09459 | M4: =Resumen[[#This Row],[Cantidad de agua en caldera (kg)]]/Resumen[[#This Row],[Horas netas de operación al año]] -> 20058.38 | N4: 37026 | P4: 37026 | Q4: =P4/F4*1000 -> 229.02829 | R4: =P4/F4 -> 0.22902829 | S4: 37026 | T4: 22633 | U4: =T4/F4 -> 0.13999884 | V4: =T4*1000/F4 -> 139.99884 | W4: 15843.1 | X4: =W4/T4 -> 0.7 | Y4: 7275 | Z4: =Y4/F4 -> 0.045000291 | AA4: =AB4*1000/F4 -> 36.92195 | AB4: 5969.01 | AC4: =AB4/Y4 -> 0.82048247 | AD4: 106699.31 | AE4: =AD4/F4 -> 0.66 | AF4: no | AG4: no | AH4: 91573 | AI4: 2490 | AJ4: =1 -AI4/AH4 -> 0.97280858 | AM4: 0.864 | AN4: 0.136 | AO4: =$G4/$C4*AK4 -> 0 | AP4: =$G4/$C4*AL4 -> 0 | AQ4: =$G4/$C4*AM4 -> 356.54428 | AR4: =$G4/$C4*AN4 -> 56.122712 | AS4: =AO4+AP4+AQ4+AR4 -> 412.667 | AU4: =P3/C3 -> 6.7390728 | AV4: =(P3*1000*[1]Biomass_Propierties!$L$15)/1000000000 -> 275.4818 | AW4: =+LineaBASE[[#This Row],[EFB (TJ)]]*1000000/Resumen[[#This Row],[Fruta procesada]] -> 1704.0222 | AX4: =+LineaBASE[[#This Row],[EFB (TJ)]]*1000000/(Resumen[[#This Row],[Horas netas de operación al año]]*3600) -> 11.521036 | AY4: =T3/C3 -> 3.2636063 | AZ4: =T3*1000*[1]Biomass_Propierties!$N$15/1000000000 -> 249.38855 | BA4: =W3*1000*[1]Biomass_Propierties!$N$15/1000000000 -> 123.11203 | BB4: =+LineaBASE[[#This Row],[MF (TJ)]]*1000000/(Resumen[[#This Row],[Horas netas de operación al año]]*3600) -> 10.42978 | BC4: =+LineaBASE[[#This Row],[Energía fibra en caldera (TJ)]]*1000000/(Resumen[[#This Row],[Horas netas de operación al año]]*3600) -> 5.1487183 | BD4: =IF(Resumen[[#This Row],[Biomass]]=0,0,LineaBASE[[#This Row],[Fibra Caldera (MW)]]) -> 0 | BE4: =(+LineaBASE[[#This Row],[MF (TJ)]]*1000000)/Resumen[[#This Row],[Fruta procesada]] -> 1542.6196 | BF4: =Y3/C3 -> 1.6608683 | BG4: =Y3*1000*[1]Biomass_Propierties!$O$15/1000000000 -> 192.47596 | BH4: =+LineaBASE[[#This Row],[PKS (TJ)]]*1000000/Resumen[[#This Row],[Fruta procesada]] -> 1190.5807 | BI4: =AB3*1000*[1]Biomass_Propierties!$O$15/1000000000 -> 151.33063 | BJ4: =+LineaBASE[[#This Row],[PKS (TJ)]]*1000000/(Resumen[[#This Row],[Horas netas de operación al año]]*3600) -> 8.0496154 | BK4: =IF(LineaBASE[[#This Row],[Fibra cogeneración (MW)]]=0,0,LineaBASE[[#This Row],[PKS caldera (MW)]]) -> 0 | BL4: =+LineaBASE[[#This Row],[Energía cuesco en caldera (TJ)]]*1000000/(Resumen[[#This Row],[Horas netas de operación al año]]*3600) -> 6.3288595 | BM4: =+LineaBASE[[#This Row],[EFB (TJ)]]+LineaBASE[[#This Row],[MF (TJ)]]+LineaBASE[[#This Row],[PKS (TJ)]] -> 717.34632 | BN4: =+LineaBASE[[#This Row],[Total PKS (MW)]]+LineaBASE[[#This Row],[total Fibra (MW)]]+LineaBASE[[#This Row],[Potencial tusa (MW)]] -> 30.000432 | BO4: =+[1]Scenario2!AI4 -> 135.05774 | BP4: =LineaBASE[[#This Row],[POME (TJ)]]*1000000/(Resumen[[#This Row],[Horas netas de operación al año]]*3600) -> 5.6483047 | BQ4: =IF(Resumen[[#This Row],[Biogas]]=0,0,LineaBASE[[#This Row],[POME (MW)]]) -> 0 | BR4: =LineaBASE[[#This Row],[POME (TJ)]]*1000000/Resumen[[#This Row],[Fruta procesada]] -> 835.41413 | BS4: =(LineaBASE[[#This Row],[Energía cuesco en caldera (TJ)]]+LineaBASE[[#This Row],[Energía fibra en caldera (TJ)]])*1000000/F3 -> 1559.608 | BT4: =+LineaBASE[[#This Row],[Potencial especifico (POME) (MJ/ t RFF)22]]+LineaBASE[[#This Row],[Potencial especifico (cuesco) (MJ/ t RFF)]]+LineaBASE[[#This Row],[Potencial especifico (fibra) (MJ/ t RFF)]]+LineaBASE[[#This Row],[Potencial especifico (tusa) (MJ/ t RFF)]] -> 5272.6366 | BU4: =LineaBASE[[#This Row],[Boiler biomass energy (MJ/t RFF)]]*Resumen[[#This Row],[Fruta procesada]]/(Resumen[[#This Row],[Horas netas de operación al año]]*3600) -> 10.54464
C5: =SUBTOTAL(107,Resumen[Horas netas de operación al año]) -> 339.38228 | D5: =SUBTOTAL(101,Resumen[Columna1]) -> 0.72165145 | E5: =SUBTOTAL(101,Resumen[Capacidad de la Planta ( t RFF/h)]) -> 31.125239 | F5: =SUBTOTAL(109,Resumen[Fruta procesada]) -> 584356.62 | H5: =SUBTOTAL(101,Resumen[Columna2]) -> 18.785921 | L5: =SUBTOTAL(107,Resumen[Vapor especifico (kg/t rFF)]) -> 205.23524 | M5: =SUBTOTAL(101,Resumen[Consumo de vapor proceso (kG/h)]) -> 17509.135 | Q5: =SUBTOTAL(101,Resumen[Tusa por RFF]) -> 232.34416 | R5: =SUBTOTAL(107,Resumen[Ratio Tusa:RFF]) -> 0.0098781135 | V5: =SUBTOTAL(101,Resumen[Fibra por RFF]) -> 127.73259 | X5: =SUBTOTAL(101,Resumen[Relación uso fibra en caldera]) -> 0.67855628 | AA5: =SUBTOTAL(101,Resumen[Cuesco por RFF]) -> 41.769401 | AC5: =SUBTOTAL(101,Resumen[Relación uso cuesco]) -> 0.86890459 | AE5: =SUBTOTAL(107,Resumen[Efluente por RFF]) -> 0.05507173 | AH5: =SUBTOTAL(101,Resumen[DQO entrada Lagunas]) -> 87948.667 | AJ5: =SUBTOTAL(101,Resumen[Eficiencia de remoción DQO]) -> 0.96357556 | AO5: =SUBTOTAL(109,Resumen[Biomass]) -> 383.80493 | AP5: =SUBTOTAL(109,Resumen[Biogas]) -> 0 | AQ5: =SUBTOTAL(109,Resumen[Electric grid]) -> 1357.2516 | AR5: =SUBTOTAL(109,Resumen[Diesel]) -> 61.458726 | AS5: =SUBTOTAL(109,Resumen[Total]) -> 1802.5153 | AU5: =P4/C4 -> 5.5745257 | AV5: =(P4*1000*[1]Biomass_Propierties!$L$15)/1000000000 -> 238.0934 | AW5: =+LineaBASE[[#This Row],[EFB (TJ)]]*1000000/Resumen[[#This Row],[Fruta procesada]] -> #VALUE! | AX5: =+LineaBASE[[#This Row],[EFB (TJ)]]*1000000/(Resumen[[#This Row],[Horas netas de operación al año]]*3600) -> #VALUE! | AY5: =T4/C4 -> 3.407558 | AZ5: =T4*1000*[1]Biomass_Propierties!$N$15/1000000000 -> 272.06249 | BA5: =W4*1000*[1]Biomass_Propierties!$N$15/1000000000 -> 190.44374 | BB5: =+LineaBASE[[#This Row],[MF (TJ)]]*1000000/(Resumen[[#This Row],[Horas netas de operación al año]]*3600) -> #VALUE! | BC5: =+LineaBASE[[#This Row],[Energía fibra en caldera (TJ)]]*1000000/(Resumen[[#This Row],[Horas netas de operación al año]]*3600) -> #VALUE! | BD5: =IF(Resumen[[#This Row],[Biomass]]=0,0,LineaBASE[[#This Row],[Fibra Caldera (MW)]]) -> #VALUE! | BE5: =(+LineaBASE[[#This Row],[MF (TJ)]]*1000000)/Resumen[[#This Row],[Fruta procesada]] -> #VALUE! | BF5: =Y4/C4 -> 1.0953026 | BG5: =Y4*1000*[1]Biomass_Propierties!$O$15/1000000000 -> 132.62399 | BH5: =+LineaBASE[[#This Row],[PKS (TJ)]]*1000000/Resumen[[#This Row],[Fruta procesada]] -> #VALUE! | BI5: =AB4*1000*[1]Biomass_Propierties!$O$15/1000000000 -> 108.81566 | BJ5: =+LineaBASE[[#This Row],[PKS (TJ)]]*1000000/(Resumen[[#This Row],[Horas netas de operación al año]]*3600) -> #VALUE! | BK5: =IF(LineaBASE[[#This Row],[Fibra cogeneración (MW)]]=0,0,LineaBASE[[#This Row],[PKS caldera (MW)]]) -> #VALUE! | BL5: =+LineaBASE[[#This Row],[Energía cuesco en caldera (TJ)]]*1000000/(Resumen[[#This Row],[Horas netas de operación al año]]*3600) -> #VALUE! | BM5: =+LineaBASE[[#This Row],[EFB (TJ)]]+LineaBASE[[#This Row],[MF (TJ)]]+LineaBASE[[#This Row],[PKS (TJ)]] -> 642.77988 | BN5: =+LineaBASE[[#This Row],[Total PKS (MW)]]+LineaBASE[[#This Row],[total Fibra (MW)]]+LineaBASE[[#This Row],[Potencial tusa (MW)]] -> #VALUE! | BO5: =+[1]Scenario2!AI5 -> 152.50699 | BP5: =LineaBASE[[#This Row],[POME (TJ)]]*1000000/(Resumen[[#This Row],[Horas netas de operación al año]]*3600) -> #VALUE! | BQ5: =IF(Resumen[[#This Row],[Biogas]]=0,0,LineaBASE[[#This Row],[POME (MW)]]) -> #VALUE! | BR5: =LineaBASE[[#This Row],[POME (TJ)]]*1000000/Resumen[[#This Row],[Fruta procesada]] -> #VALUE! | BS5: =(LineaBASE[[#This Row],[Energía cuesco en caldera (TJ)]]+LineaBASE[[#This Row],[Energía fibra en caldera (TJ)]])*1000000/F4 -> 1851.1011 | BT5: =+LineaBASE[[#This Row],[Potencial especifico (POME) (MJ/ t RFF)22]]+LineaBASE[[#This Row],[Potencial especifico (cuesco) (MJ/ t RFF)]]+LineaBASE[[#This Row],[Potencial especifico (fibra) (MJ/ t RFF)]]+LineaBASE[[#This Row],[Potencial especifico (tusa) (MJ/ t RFF)]] -> #VALUE! | BU5: =LineaBASE[[#This Row],[Boiler biomass energy (MJ/t RFF)]]*Resumen[[#This Row],[Fruta procesada]]/(Resumen[[#This Row],[Horas netas de operación al año]]*3600) -> #VALUE!
AU6: Total | AV6: =SUBTOTAL(109,LineaBASE[EFB (TJ)]) -> #REF! | AW6: =SUBTOTAL(107,LineaBASE[Potencial especifico (tusa) (MJ/ t RFF)]) -> #REF! | AX6: =SUBTOTAL(109,LineaBASE[Potencial tusa (MW)]) -> #REF! | AZ6: =SUBTOTAL(109,LineaBASE[MF (TJ)]) -> #REF! | BA6: =SUBTOTAL(109,LineaBASE[Energía fibra en caldera (TJ)]) -> #REF! | BB6: =SUBTOTAL(109,LineaBASE[total Fibra (MW)]) -> #REF! | BC6: =SUBTOTAL(109,LineaBASE[Fibra Caldera (MW)]) -> #REF! | BD6: =SUBTOTAL(109,LineaBASE[Fibra cogeneración (MW)]) -> #VALUE! | BE6: =SUBTOTAL(107,LineaBASE[Potencial especifico (fibra) (MJ/ t RFF)]) -> #REF! | BG6: =SUBTOTAL(109,LineaBASE[PKS (TJ)]) -> #REF! | BH6: =SUBTOTAL(107,LineaBASE[Potencial especifico (cuesco) (MJ/ t RFF)]) -> #REF! | BI6: =SUBTOTAL(109,LineaBASE[Energía cuesco en caldera (TJ)]) -> #REF! | BJ6: =SUBTOTAL(109,LineaBASE[Total PKS (MW)]) -> #REF! | BK6: =SUBTOTAL(109,LineaBASE[PKS Cogen]) -> #VALUE! | BL6: =SUBTOTAL(109,LineaBASE[PKS caldera (MW)]) -> #REF! | BM6: =SUBTOTAL(109,LineaBASE[Potencial energético biomasa solida (TJ)]) -> #REF! | BN6: =SUBTOTAL(109,LineaBASE[Potencial energético (MW)]) -> #REF! | BO6: =SUBTOTAL(109,LineaBASE[POME (TJ)]) -> 287.56473 | BP6: =SUBTOTAL(109,LineaBASE[POME (MW)]) -> #VALUE! | BQ6: =SUBTOTAL(109,LineaBASE[Columna1]) -> #VALUE! | BR6: =SUBTOTAL(107,LineaBASE[Potencial especifico (POME) (MJ/ t RFF)22]) -> #VALUE! | BT6: =SUBTOTAL(101,LineaBASE[Biomass energy potential]) -> #REF!

Sheet EE_PB
D2: 30 | E2: 40 | F2: 30 | G2: 24 | H2: 24 | I2: 20 | M2: 30 | N2: 40 | O2: 30 | P2: 24 | Q2: 24 | R2: 20
B3: Parametro | C3: Unidad | D3: Planta extractora
D4: Palmaceite Planta A | E4: Aceites Planta B | F4: Extrarsa Planta C | G4: Tequendama Planta D | H4: Gradesa Planta E | I4: Padelma Planta F
B5: Consumo de vapor en proceso | C5: kg t RFF-1 | D5: 542 | E5: 442 | F5: 452 | G5: 517 | H5: 430 | I5: 470 | T5: =+Scenarios1!#REF!*M2 -> #REF! | U5: =+Scenarios1!#REF!*N2 -> #REF! | V5: =+Scenarios1!#REF!*O2 -> #REF! | W5: =+Scenarios1!#REF!*P2 -> #REF! | X5: =+Scenarios1!#REF!*Q2 -> #REF! | Y5: =+Scenarios1!#REF!*R2 -> #REF!
B6: Consumo de electricidad en PB | C6: kWh t RFF-1 | D6: 19.5 | E6: 18.7 | F6: 20.1 | G6: 20.4 | H6: 21.7 | I6: 18.9 | J6: =+AVERAGE(D6:I6) -> 19.883333 | T6: =+L22*M2 -> 23175 | U6: =+O22*N2 -> 26304 | V6: =+R22*O2 -> 19458 | W6: =+U22*P2 -> 16358.4 | X6: =+X22*Q2 -> 21749.76 | Y6: =+AA22*R2 -> 7280
B7: Consumo de diésel en PB | C7: L t RFF-1 | D7: 0.01 | E7: 0.38 | F7: 0.02 | G7: 0.09 | H7: 0.04 | I7: 0.1 | J7: 49.17 | K7: =+J7/J6 -> 2.4729254
B8: Biomasa usada como combustible
B9: Cuesco | C9: kg t RFF-1 | D9: 58.2 | E9: 105.5 | F9: 98 | G9: 102.7 | H9: =+H41/H17*1000 -> 125.02886 | I9: =+I41/I17*1000 -> 125.09479
B10: Fibra | C10: kg t RFF-1 | D10: 47.2 | E10: 41.2 | F10: 36.9 | G10: 31.28 | H10: 42.5 | I10: 45.9
B11: Raquis | C11: kg t RFF-1 | D11: 243.5 | E11: 224.6 | F11: 229 | G11: 185.5 | H11: 243.3 | I11: 213.5
B12: Eficiencia térmica/electrica sistema de combustión | C12: % | D12: 76/13 | E12: 55/0 | F12: 62/0 | G12: 53/0 | H12: 65/0% | I12: 47/0
B13: Eficiencia eléctrica planta de biogás | C13: % | D13: N.A. | E13: N.A. | F13: N.A. | G13: 15 | H13: N.A. | I13: N.A.
L14: =+D15 -> Planta A | O14: =+E15 -> Planta B | R14: =+F15 -> Planta C | U14: =+G15 -> Planta D | X14: =+H15 -> Planta E | AA14: =+I15 -> Planta F
D15: Planta A | E15: Planta B | F15: Planta C | G15: Planta D | H15: Planta E | I15: Planta F | L15: LB | M15: ERI - 1 | N15: ERI - 2 | O15: LB | P15: ERI - 1 | Q15: ERI - 2 | R15: LB | S15: ERI - 1 | T15: ERI - 2 | U15: LB | V15: ERI - 1 | W15: ERI - 2 | X15: LB | Y15: ERI - 1 | Z15: ERI - 2 | AA15: LB | AB15: ERI - 1 | AC15: ERI - 2
B16: Capacidad de procesamiento | C16: tRFF h-1 | D16: 30000 | E16: 40000 | F16: 30000 | G16: 24000 | H16: 24000 | I16: 15000 | K16: Combustion | L16: 850 | M16: 4950 | N16: 2100 | P16: 6600 | Q16: 2800 | S16: 4950 | T16: 2100 | U16: 0 | V16: 3960 | W16: 1680 | X16: 0 | Y16: 3960 | Z16: 1680 | AA16: 0 | AB16: 3300 | AC16: 1400 | AD16: =+M16+P16+S16+V16+Y16+AB16 -> 27720 | AE16: =+N16+Q16+T16+W16+Z16+AC16 -> 11760
B17: Fruto procesado | C17: tRFF año-1 | D17: 153157 | E17: 206207 | F17: 177589 | G17: 131909 | H17: 75534 | I17: 38620 | K17: Digestión anerobica | L17: 0 | M17: 1590 | N17: 4110 | P17: 2120 | Q17: 5480 | S17: 1590 | T17: 4110 | U17: 600 | V17: 1272 | W17: 3288 | X17: 0 | Y17: 1272 | Z17: 3288 | AA17: 0 | AB17: 1060 | AC17: 2740 | AD17: =+M17+P17+S17+V17+Y17+AB17 -> 8904 | AE17: =+N17+Q17+T17+W17+Z17+AC17 -> 23016
B18: Horas de operación | C18: h año-1 | D18: =+D17/D16*1000 -> 5105.2333 | E18: =+E17/E16*1000 -> 5155.175 | F18: =+F17/F16*1000 -> 5919.6333 | G18: =+G17/G16*1000 -> 5496.2083 | H18: =+H17/H16*1000 -> 3147.25 | I18: =+I17/I16*1000 -> 2574.6667 | AD18: =SUM(AD16:AD17) -> 36624 | AE18: =SUM(AE16:AE17) -> 34776
B19: Tasa de extracción aceite | C19: % ACP tRFF-1 | D19: 20.71 | E19: 20.55 | F19: 19.68 | G19: 19.9 | H19: 20.77 | I19: 19.3 | M19: =+M22/D2 -> 54.016019 | N19: =+N22/D2 -> 43.653257 | P19: =+P22/E2 -> 56.994476 | Q19: =+Q22/E2 -> 47.60571 | S19: =+S22/F2 -> 48.737355 | T19: =+T22/F2 -> 46.469273 | V19: =+V22/G2 -> 66.26111 | W19: =+W22/G2 -> 49.845496 | Y19: =+Y22/H2 -> 61.901985 | Z19: =+Z22/H2 -> 61.770828 | AB19: =+AB22/I2 -> 65.067496 | AC19: =+AC22/I2 -> 45.700514 | AD19: =+AD18/410000 -> 0.089326829 | AE19: =+AE18/410000 -> 0.084819512
B20: Aceite crudo producido | C20: tACP año-1 | D20: =+D17*D19/100 -> 31718.815 | E20: =+E17*E19/100 -> 42375.539 | F20: =+F17*F19/100 -> 34949.515 | G20: =+G17*G19/100 -> 26249.891 | H20: =+H17*H19/100 -> 15688.412 | I20: =+I17*I19/100 -> 7453.66 | L20: =+L14 -> Planta A | O20: =+O14 -> Planta B | R20: =+R14 -> Planta C | U20: =+U14 -> Planta D | X20: =+X14 -> Planta E | AA20: =+AA14 -> Planta F | AF20: =+L20 -> Planta A | AH20: =+O20 -> Planta B | AJ20: =+R20 -> Planta C | AL20: =+U20 -> Planta D | AN20: =+X20 -> Planta E | AP20: =+AA20 -> Planta F | AU20: =AF27 -> LB | AW20: =AH27 -> ERI - 1 | AY20: =AJ27 -> ERI - 2 | BC20: η Proceso | BF20: Iexc
B21: PKO producido | C21: tPKO año-1 | D21: 7636 | E21: 10292 | F21: 7926 | G21: 5576 | H21: 2803 | I21: 2177 | L21: LB | M21: ERI - 1 | N21: ERI - 2 | O21: LB | P21: ERI - 1 | Q21: ERI - 2 | R21: LB | S21: ERI - 1 | T21: ERI - 2 | U21: LB | V21: ERI - 1 | W21: ERI - 2 | X21: LB | Y21: ERI - 1 | Z21: ERI - 2 | AA21: LB | AB21: ERI - 1 | AC21: ERI - 2 | AF21: η Proceso | AG21: Iexc | AH21: η Proceso | AI21: Iexc | AJ21: η Proceso | AK21: Iexc | AL21: η Proceso | AM21: Iexc | AN21: η Proceso | AO21: Iexc | AP21: η Proceso | AQ21: Iexc | AU21: =AF28 -> η Proceso | AV21: =AG28 -> Iexc | AW21: =AH28 -> η Proceso | AX21: =AI28 -> Iexc | AY21: =AJ28 -> η Proceso | AZ21: =AK28 -> Iexc | BC21: LB | BD21: ERI - 1 | BE21: ERI - 2 | BF21: LB | BG21: ERI - 1 | BH21: ERI - 2
